<?xml version="1.0"?>
<robot xmlns:xacro="http://www.ros.org/wiki/xacro" name="kuka_lwr">

 <xacro:property name="M_PI" value="3.1415926535897931" />
 <xacro:property name="name" value="kuka" />
 <xacro:property name="inertia_scaling" value="1" />
  <!--
     Little helper macro to define the inertia matrix needed
     for links.
     -->
  <!-- width is along x axis
       length is along y axis
       height is along z axis
  -->
  <gazebo>
      <plugin filename="libgazebo_ros_control.so" name="gazebo_ros_control">
        <robotNamespace>/kuka</robotNamespace>
        <robotSimType>gazebo_ros_control/DefaultRobotHWSim</robotSimType>
      </plugin>
  </gazebo>

  <xacro:macro name="cuboid_inertia_def" params="width height length mass">
    <inertia ixx="${mass * (height * height + length * length) / 12 * inertia_scaling}"
             iyy="${mass * (width * width + height * height) / 12 * inertia_scaling}"
             izz="${mass * (width * width + length * length) / 12 * inertia_scaling}"
             ixy="0" iyz="0" ixz="0"/>
  </xacro:macro>

  <!-- length is along the y-axis! -->
  <xacro:macro name="cylinder_inertia_def" params="radius length mass">
    <inertia ixx="${mass * (3 * radius * radius + length * length) / 12 * inertia_scaling}"
             iyy="${mass * radius* radius / 2 * inertia_scaling}"
             izz="${mass * (3 * radius * radius + length * length) / 12 * inertia_scaling}"
             ixy="0" iyz="0" ixz="0"/>
  </xacro:macro>

  <xacro:property name="arm_elem_link_mass" value="2.0"/>
  <xacro:property name="arm_elem_ball_link_mass" value="2.0"/>
  <xacro:property name="arm_elem_end_link_mass" value="2.0"/>
  <xacro:property name="safety_controller_k_pos" value="100" />
  <xacro:property name="safety_controller_k_vel" value="2" />
  <xacro:property name="joint_damping" value="0" />

  <xacro:property name="arm_velocity_scale_factor" value="1"/>
  <xacro:property name="right" value="0" />
  <!-- right is either 1 (for right arm) or -1 (for left arm) -->
    <link name="world"/>
    <joint name="base_joint" type="fixed">
      <origin xyz="0 0 0.055" rpy="0 0 0"/>
      <axis xyz="0 0 1"/>
      <child link="calib_${name}_arm_base_link"/>
      <parent link="world"/>
    </joint>

    <link name="calib_${name}_arm_base_link">
      <inertial>
        <mass value="2"/> <!-- static base, disable dynamics for this link -->
        <origin xyz="0 0 0.055" rpy="0 0 0"/>
        <xacro:cylinder_inertia_def radius="0.06" length="0.11"
                              mass="2"/>
      </inertial>
      <visual>
        <origin xyz="0 0 0" rpy="0 0 0"/>
        <geometry>
          <mesh filename="package://lmtlwr/model/meshes_arm/arm_base.stl"/>
        </geometry>
        <material name="Orange"/>
      </visual>
      <collision>
        <origin xyz="0 0 0" rpy="0 0 0"/>
        <geometry>
          <mesh filename="package://lmtlwr/model/meshes_arm/convex/arm_base_convex.stl"/>
        </geometry>
      </collision>
    </link>

    <link name="${name}_arm_1_link">
      <inertial>
        <mass value="${arm_elem_link_mass}"/>
        <origin rpy="0 0 0" xyz="0 0.04 0.130"/>
        <xacro:cuboid_inertia_def length="0.12" width="0.06" height="0.260"
                            mass="${arm_elem_link_mass}"/>
      </inertial>
      <visual>
        <origin xyz="0 0 0" rpy="0 0 ${M_PI}"/>
        <geometry>
          <mesh filename="package://lmtlwr/model/meshes_arm/arm_segment_a.stl"/>
        </geometry>
        <material name="Orange"/>
      </visual>
      <collision>
        <origin xyz="0 0 0" rpy="0 0 ${M_PI}"/>
        <geometry>
          <mesh filename="package://lmtlwr/model/meshes_arm/convex/arm_segment_a_convex.stl"/>
        </geometry>
      </collision>
    </link>

    <joint name="${name}_arm_0_joint" type="revolute">
      <origin xyz="0 0 0.11" rpy="0 0 0"/>
      <!-- <origin xyz="0 0.04 0.13" rpy="0 0 0"/> -->
      <axis xyz="0 0 1"/>
      <limit lower="${-170 * M_PI / 180}" upper="${170 * M_PI / 180}"
             effort="204" velocity="${arm_velocity_scale_factor * 110 * M_PI / 180}" />
      <dynamics damping="${joint_damping}"/>
      <parent link="calib_${name}_arm_base_link"/>
      <child link="${name}_arm_1_link"/>
    </joint>

    <transmission name="${name}_arm_0_trans">
      <type>transmission_interface/SimpleTransmission</type>
      <actuator name="${name}_arm_0_motor">
        <hardwareInterface>hardware_interface/EffortJointInterface</hardwareInterface>
        <mechanicalReduction>1.0</mechanicalReduction>
      </actuator>
      <joint name="${name}_arm_0_joint">
        <hardwareInterface>hardware_interface/EffortJointInterface</hardwareInterface>
      </joint>

    </transmission>

    <link name="${name}_arm_2_link">
      <inertial>
        <mass value="${arm_elem_link_mass}"/>
        <origin rpy="0 0 0" xyz="0 -0.04 ${0.130 - 0.06}"/>
        <xacro:cuboid_inertia_def length="0.12" width="0.06" height="0.260"
                            mass="${arm_elem_link_mass}"/>
      </inertial>

      <visual>
        <origin xyz="0 0 0.2" rpy="${M_PI} 0 ${M_PI}"/>
        <geometry>
          <mesh filename="package://lmtlwr/model/meshes_arm/arm_segment_b.stl"/>
        </geometry>
        <material name="Orange"/>
      </visual>

      <collision>
        <origin xyz="0 0 0.2" rpy="${M_PI} 0 ${M_PI}"/>
        <geometry>
          <mesh filename="package://lmtlwr/model/meshes_arm/convex/arm_segment_b_convex.stl"/>
        </geometry>
      </collision>
    </link>

    <joint name="${name}_arm_1_joint" type="revolute">
      <origin xyz="0 0 0.20" rpy="0 0 0"/>
      <origin rpy="0 0 0" xyz="0 -0.04 ${0.130 - 0.06}"/>
      <axis xyz="0 -1 0"/>
      <limit lower="${-90 * M_PI / 180}" upper="${90 * M_PI / 180}"
             effort="306" velocity="${arm_velocity_scale_factor * 0 * M_PI / 180}" />
      <dynamics damping="${joint_damping}"/>
      <parent link="${name}_arm_1_link"/>
      <child link="${name}_arm_2_link"/>
    </joint>

    <transmission name="${name}_arm_1_trans">
      <type>transmission_interface/SimpleTransmission</type>
      <actuator name="${name}_arm_1_motor">
        <hardwareInterface>hardware_interface/EffortJointInterface</hardwareInterface>
        <mechanicalReduction>1.0</mechanicalReduction>
      </actuator>
      <joint name="${name}_arm_1_joint">
        <hardwareInterface>hardware_interface/EffortJointInterface</hardwareInterface>
      </joint>
    </transmission>

    <link name="${name}_arm_3_link">
      <inertial>
        <mass value="${arm_elem_link_mass}"/>
        <origin rpy="0 0 0" xyz="0 -0.04 0.130"/>
        <xacro:cuboid_inertia_def length="0.12" width="0.06" height="0.260"
                            mass="${arm_elem_link_mass}"/>
      </inertial>

      <visual>
        <origin xyz="0 0 0" rpy="0 0 0"/>
        <geometry>
          <mesh filename="package://lmtlwr/model/meshes_arm/arm_segment_a.stl"/>
        </geometry>
        <material name="Orange"/>
      </visual>

      <collision>
        <origin xyz="0 0 0" rpy="0 0 0"/>
        <geometry>
          <mesh filename="package://lmtlwr/model/meshes_arm/convex/arm_segment_a_convex.stl"/>
        </geometry>
      </collision>
    </link>

    <joint name="${name}_arm_2_joint" type="revolute">
      <origin xyz="0 0 0.20" rpy="0 0 0"/>
      <!-- <origin rpy="0 0 0" xyz="0 -0.04 0.130"/> -->
      <axis xyz="0 0 1"/>
      <limit lower="${-170 * M_PI / 180}" upper="${170 * M_PI / 180}"
             effort="204" velocity="${arm_velocity_scale_factor * 130 * M_PI / 180}" />
      <dynamics damping="${joint_damping}"/>
      <parent link="${name}_arm_2_link"/>
      <child link="${name}_arm_3_link"/>
    </joint>

    <transmission name="${name}_arm_2_trans">
      <type>transmission_interface/SimpleTransmission</type>
      <actuator name="${name}_arm_2_motor">
        <hardwareInterface>hardware_interface/EffortJointInterface</hardwareInterface>
        <mechanicalReduction>1.0</mechanicalReduction>
      </actuator>
      <joint name="${name}_arm_2_joint">
        <hardwareInterface>hardware_interface/EffortJointInterface</hardwareInterface>
      </joint>
    </transmission>

    <link name="${name}_arm_4_link">
      <inertial>
        <mass value="${arm_elem_link_mass}"/>
        <origin rpy="0 0 0" xyz="0 0.04 ${0.130 - 0.06}"/>
        <xacro:cuboid_inertia_def length="0.12" width="0.06" height="0.2600"
                            mass="${arm_elem_link_mass}"/>
      </inertial>
      <visual>
        <origin xyz="0 0 0.2" rpy="0 ${M_PI} ${M_PI}"/>
        <geometry>
          <mesh filename="package://lmtlwr/model/meshes_arm/arm_segment_b.stl"/>
        </geometry>
        <material name="Orange"/>
      </visual>
      <collision>
        <origin xyz="0 0 0.2" rpy="0 ${M_PI} ${M_PI}"/>
        <geometry>
          <mesh filename="package://lmtlwr/model/meshes_arm/convex/arm_segment_b_convex.stl"/>
        </geometry>
      </collision>
    </link>


    <joint name="${name}_arm_3_joint" type="revolute">
      <origin xyz="0 0 0.20" rpy="0 0 0"/>
      <!-- <origin rpy="0 0 0" xyz="0 0.04 ${0.130 - 0.06}"/> -->
      <axis xyz="0 1 0"/>
      <limit lower="${-120 * M_PI / 180}" upper="${120 * M_PI / 180}"
             effort="306" velocity="${arm_velocity_scale_factor * 130 * M_PI / 180}" />
      <dynamics damping="${joint_damping}"/>
      <parent link="${name}_arm_3_link"/>
      <child link="${name}_arm_4_link"/>
    </joint>

    <transmission name="${name}_arm_3_trans">
      <type>transmission_interface/SimpleTransmission</type>
      <actuator name="${name}_arm_3_motor">
        <hardwareInterface>hardware_interface/EffortJointInterface</hardwareInterface>
        <mechanicalReduction>1.0</mechanicalReduction>
      </actuator>
      <joint name="${name}_arm_3_joint">
        <hardwareInterface>hardware_interface/EffortJointInterface</hardwareInterface>
      </joint>
    </transmission>

    <link name="${name}_arm_5_link">
      <inertial>
        <mass value="${arm_elem_link_mass}"/>
        <origin rpy="0 0 0" xyz="0 0.02 0.124"/>
        <xacro:cuboid_inertia_def length="0.12" width="0.06" height="0.248"
                            mass="${arm_elem_link_mass}"/>
      </inertial>

      <visual>
        <origin xyz="0 0 0" rpy="0 0 ${M_PI}"/>
        <geometry name="${name}_arm_5_geom">
          <mesh filename="package://lmtlwr/model/meshes_arm/arm_segment_last.stl"/>
        </geometry>
        <material name="Orange"/>
      </visual>

      <collision>
        <origin xyz="0 0 0" rpy="0 0 ${M_PI}"/>
        <geometry>
          <mesh filename="package://lmtlwr/model/meshes_arm/convex/arm_segment_last_convex.stl"/>
        </geometry>
      </collision>
    </link>

    <joint name="${name}_arm_4_joint" type="revolute">
      <origin xyz="0 0 0.20" rpy="0 0 0"/>
      <!-- <origin rpy="0 0 0" xyz="0 0.02 0.124"/> -->
      <axis xyz="0 0 1"/>
      <limit lower="${-170 * M_PI / 180}" upper="${170 * M_PI / 180}"
             effort="204" velocity="${arm_velocity_scale_factor * 130 * M_PI / 180}" />
      <dynamics damping="${joint_damping}"/>
      <parent link="${name}_arm_4_link"/>
      <child link="${name}_arm_5_link"/>
    </joint>

    <transmission name="${name}_arm_4_trans">
      <type>transmission_interface/SimpleTransmission</type>
      <actuator name="${name}_arm_4_motor">
        <hardwareInterface>hardware_interface/EffortJointInterface</hardwareInterface>
        <mechanicalReduction>1.0</mechanicalReduction>
      </actuator>
      <joint name="${name}_arm_4_joint">
        <hardwareInterface>hardware_interface/EffortJointInterface</hardwareInterface>
      </joint>
    </transmission>

    <link name="${name}_arm_6_link">
      <inertial>
        <mass value="${arm_elem_ball_link_mass}"/>
        <origin rpy="0 0 0" xyz="0 0 0"/>
        <xacro:cuboid_inertia_def length="0.125" width="0.125" height="0.125"
                            mass="${arm_elem_ball_link_mass}"/>
      </inertial>

      <visual>
        <origin xyz="0 0 0" rpy="0 0 ${M_PI}"/>
        <geometry>
          <mesh filename="package://lmtlwr/model/meshes_arm/arm_wrist.stl"/>
        </geometry>
        <material name="Grey"/>
      </visual>

      <collision>
        <origin xyz="0 0 0" rpy="0 0 ${M_PI}"/>
        <geometry>
          <mesh filename="package://lmtlwr/model/meshes_arm/convex/arm_wrist_convex.stl"/>
        </geometry>
      </collision>
    </link>

    <joint name="${name}_arm_5_joint" type="revolute">
      <origin xyz="0 0 0.19" rpy="0 0 0"/>
      <!-- <origin rpy="0 0 0" xyz="0 0 0"/> -->
      <axis xyz="0 -1 0"/>
      <limit lower="${-120 * M_PI / 180}" upper="${120 * M_PI / 180}"
             effort="306" velocity="${arm_velocity_scale_factor * 180 * M_PI / 180}" />
      <dynamics damping="${joint_damping}"/>
      <parent link="${name}_arm_5_link"/>
      <child link="${name}_arm_6_link"/>
    </joint>

    <transmission name="${name}_arm_5_trans">
      <type>transmission_interface/SimpleTransmission</type>
      <actuator name="${name}_arm_5_motor">
        <hardwareInterface>hardware_interface/EffortJointInterface</hardwareInterface>
        <mechanicalReduction>1.0</mechanicalReduction>
      </actuator>
      <joint name="${name}_arm_5_joint">
        <hardwareInterface>hardware_interface/EffortJointInterface</hardwareInterface>
      </joint>
    </transmission>

    <link name="${name}_arm_7_link">
      <inertial>
        <mass value="${arm_elem_end_link_mass}"/>
        <origin xyz="0 0 0" rpy="0 0 ${right * -1/4 * M_PI  +  M_PI}"/>
        <xacro:cuboid_inertia_def length="0.05" width="0.05" height="0.05"
                            mass="${arm_elem_end_link_mass}"/>
      </inertial>
      <visual>
        <origin xyz="0 0 0" rpy="0 0 ${right * -1/4 * M_PI  +  M_PI}"/>
        <geometry>
          <mesh filename="package://lmtlwr/model/meshes_arm/arm_flanche.stl"/>
        </geometry>
        <material name="Grey"/>
      </visual>
      <collision>
        <origin xyz="0 0 0" rpy="0 0 ${right * -1/4 * M_PI  +  M_PI}"/>
        <geometry>
          <mesh filename="package://lmtlwr/model/meshes_arm/convex/arm_flanche_convex.stl"/>
        </geometry>
      </collision>
    </link>

    <joint name="${name}_arm_6_joint" type="revolute">
      <origin xyz="0 0 0.078" rpy="0 0 0"/>
      <!-- <origin xyz="0 0 0"/> -->
      <axis xyz="0 0 1"/>
      <limit lower="${-170 * M_PI / 180}" upper="${170 * M_PI / 180}"
             effort="204" velocity="${arm_velocity_scale_factor * 180 * M_PI / 180}" />
      <dynamics damping="${joint_damping}"/>
      <parent link="${name}_arm_6_link"/>
      <child link="${name}_arm_7_link"/>
    </joint>

    <transmission name="${name}_arm_6_trans">
      <type>transmission_interface/SimpleTransmission</type>
      <actuator name="${name}_arm_6_motor">
        <hardwareInterface>hardware_interface/EffortJointInterface</hardwareInterface>
        <mechanicalReduction>1.0</mechanicalReduction>
      </actuator>
      <joint name="${name}_arm_6_joint">
        <hardwareInterface>hardware_interface/EffortJointInterface</hardwareInterface>
      </joint>
    </transmission>



</robot>
